<?xml version='1.0' encoding='utf-8'?>
<robot name="chronos">
    <link name="motor_mx2L">
        <inertial>
            <origin xyz="-5.6522082427790113e-08 -0.020555762477523203 -0.014758994299780143" rpy="0.0 -9.495567745759799e-66 0.0" />
            <mass value="0.47580795836458334" />
            <inertia ixx="0.0001897586606890156" iyy="0.0001575391670494558" izz="0.00010384391047283528" ixy="-1.0661006001611015e-09" iyz="4.171260414954219e-06" ixz="2.0110208517040733e-09" />
        </inertial>
        <visual name="motor_mx2L_visual">
            <origin xyz="0.07501570176619629 -0.3745598895623257 0.22557026365620686" rpy="3.127268897151319 -2.3411986808127356e-05 3.1289109011922998" />
            <geometry>
                <mesh filename="package://chronos_balance/urdf/meshes/motor_mx2L.stl" scale="0.001 0.001 0.001" />
            </geometry>
        </visual>
        <collision name="motor_mx2L_collision">
            <origin xyz="0.07501570176619629 -0.3745598895623257 0.22557026365620686" rpy="3.127268897151319 -2.3411986808127356e-05 3.1289109011922998" />
            <geometry>
                <mesh filename="package://chronos_balance/urdf/meshes/motor_mx2L.stl" scale="0.001 0.001 0.001" />
            </geometry>
        </collision>
    </link>
    <link name="motor_mx2R">
        <inertial>
            <origin xyz="-5.704140859208451e-08 -0.02055576183836486 -0.014758994860178802" rpy="0.0 -9.495567745759799e-66 0.0" />
            <mass value="0.4758079584031028" />
            <inertia ixx="0.00018975870874078649" iyy="0.00015753911638176007" izz="0.00010384387769192535" ixy="-1.1590770496172629e-09" iyz="4.171282826901517e-06" ixz="2.0741366516169344e-09" />
        </inertial>
        <visual name="motor_mx2R_visual">
            <origin xyz="0.162897701786426 -0.37456136462365025 0.22557019687714533" rpy="3.127268897151319 -2.3411986808123093e-05 3.128910901192301" />
            <geometry>
                <mesh filename="package://chronos_balance/urdf/meshes/motor_mx2R.stl" scale="0.001 0.001 0.001" />
            </geometry>
        </visual>
        <collision name="motor_mx2R_collision">
            <origin xyz="0.162897701786426 -0.37456136462365025 0.22557019687714533" rpy="3.127268897151319 -2.3411986808123093e-05 3.128910901192301" />
            <geometry>
                <mesh filename="package://chronos_balance/urdf/meshes/motor_mx2R.stl" scale="0.001 0.001 0.001" />
            </geometry>
        </collision>
    </link>
    <link name="motor_bracket_a">
        <inertial>
            <origin xyz="-0.31634090136271636 -0.4779800513966333 0.06553511359550282" rpy="0.0 -0.0 0.0" />
            <mass value="0.23368391804045266" />
            <inertia ixx="0.0003487435319698244" iyy="0.00017363338403524053" izz="0.0002935167509461739" ixy="-1.4590461585445302e-08" iyz="5.559870605593639e-05" ixz="1.15202875364262e-08" />
        </inertial>
        <visual name="motor_bracket_a_visual">
            <origin xyz="-0.24340047520169283 -0.7261819051311471 -0.24436409652801433" rpy="1.5564722734354768 -0.012681752394016548 -3.141569239720221" />
            <geometry>
                <mesh filename="package://chronos_balance/urdf/meshes/motor_bracket_a.stl" scale="0.001 0.001 0.001" />
            </geometry>
        </visual>
        <collision name="motor_bracket_a_collision">
            <origin xyz="-0.24340047520169283 -0.7261819051311471 -0.24436409652801433" rpy="1.5564722734354768 -0.012681752394016548 -3.141569239720221" />
            <geometry>
                <mesh filename="package://chronos_balance/urdf/meshes/motor_bracket_a.stl" scale="0.001 0.001 0.001" />
            </geometry>
        </collision>
    </link>
    <link name="motor_bracket_b">
        <inertial>
            <origin xyz="-0.1430839513953675 -0.4790948220842655 0.06551972275487561" rpy="0.0 -0.0 0.0" />
            <mass value="0.23368391804045266" />
            <inertia ixx="0.00034874353197037605" iyy="0.00017363338403487277" izz="0.00029351675094610105" ixy="-1.4590461822235057e-08" iyz="5.5598706056047414e-05" ixz="1.1520287495660197e-08" />
        </inertial>
        <visual name="motor_bracket_b_visual">
            <origin xyz="-0.07014352523434174 -0.7272966758187787 -0.24437948736864268" rpy="1.5564722734354741 -0.012681752394017672 -3.141569239720221" />
            <geometry>
                <mesh filename="package://chronos_balance/urdf/meshes/motor_bracket_b.stl" scale="0.001 0.001 0.001" />
            </geometry>
        </visual>
        <collision name="motor_bracket_b_collision">
            <origin xyz="-0.07014352523434174 -0.7272966758187787 -0.24437948736864268" rpy="1.5564722734354741 -0.012681752394017672 -3.141569239720221" />
            <geometry>
                <mesh filename="package://chronos_balance/urdf/meshes/motor_bracket_b.stl" scale="0.001 0.001 0.001" />
            </geometry>
        </collision>
    </link>
    <link name="motor_upper_a">
        <inertial>
            <origin xyz="0.015209766213301307 -0.015391734911888921 0.015493083011493667" rpy="0.0 -3.388131789017202e-21 0.0" />
            <mass value="0.34532389787865936" />
            <inertia ixx="9.878415769591356e-05" iyy="8.183259382588449e-05" izz="6.115506697764989e-05" ixy="1.3341410933929639e-08" iyz="-2.956727393304745e-06" ixz="-5.486134168706815e-07" />
        </inertial>
        <visual name="motor_upper_a_visual">
            <origin xyz="-0.1479082463709332 -0.2889059445177528 0.29274501392888486" rpy="-1.5743739348662287 0.012658611786859921 0.00011286496484090239" />
            <geometry>
                <mesh filename="package://chronos_balance/urdf/meshes/motor_upper_a.stl" scale="0.001 0.001 0.001" />
            </geometry>
        </visual>
        <collision name="motor_upper_a_collision">
            <origin xyz="-0.1479082463709332 -0.2889059445177528 0.29274501392888486" rpy="-1.5743739348662287 0.012658611786859921 0.00011286496484090239" />
            <geometry>
                <mesh filename="package://chronos_balance/urdf/meshes/motor_upper_a.stl" scale="0.001 0.001 0.001" />
            </geometry>
        </collision>
    </link>
    <link name="motor_upper_b">
        <inertial>
            <origin xyz="0.015209766180666478 -0.015391734215260638 0.015493082178301806" rpy="-1.734723475976807e-18 -0.0 0.0" />
            <mass value="0.34532389787865936" />
            <inertia ixx="9.878415769557355e-05" iyy="8.183259381453292e-05" izz="6.115506698926782e-05" ixy="1.3341410548782186e-08" iyz="-2.9567273932861397e-06" ixz="-5.486134168291185e-07" />
        </inertial>
        <visual name="motor_upper_b_visual">
            <origin xyz="-0.14790824640354505 -0.288905943821064 0.29274501309568207" rpy="-1.5743739348662271 0.012658611786858807 0.00011286496484089211" />
            <geometry>
                <mesh filename="package://chronos_balance/urdf/meshes/motor_upper_b.stl" scale="0.001 0.001 0.001" />
            </geometry>
        </visual>
        <collision name="motor_upper_b_collision">
            <origin xyz="-0.14790824640354505 -0.288905943821064 0.29274501309568207" rpy="-1.5743739348662271 0.012658611786858807 0.00011286496484089211" />
            <geometry>
                <mesh filename="package://chronos_balance/urdf/meshes/motor_upper_b.stl" scale="0.001 0.001 0.001" />
            </geometry>
        </collision>
    </link>
    <link name="outer_ball_bearing">
        <inertial>
            <origin xyz="3.905698111594802e-09 -0.0024189373499051213 -1.73401634781456e-05" rpy="0.0 -0.0 0.0" />
            <mass value="0.009488893653327652" />
            <inertia ixx="5.478193889399525e-07" iyy="1.0829294813290333e-06" izz="5.478468828123551e-07" ixy="-2.8396609960700027e-13" iyz="3.835261720388626e-09" ixz="-5.361503703526252e-15" />
        </inertial>
        <visual name="outer_ball_bearing_visual">
            <origin xyz="0.22701738888115006 -0.0519155475538388 -0.29902142964694345" rpy="1.5706697301302144 -0.019831078117979517 1.5709572065322945" />
            <geometry>
                <mesh filename="package://chronos_balance/urdf/meshes/outer_ball_bearing.stl" scale="0.001 0.001 0.001" />
            </geometry>
        </visual>
        <collision name="outer_ball_bearing_collision">
            <origin xyz="0.22701738888115006 -0.0519155475538388 -0.29902142964694345" rpy="1.5706697301302144 -0.019831078117979517 1.5709572065322945" />
            <geometry>
                <mesh filename="package://chronos_balance/urdf/meshes/outer_ball_bearing.stl" scale="0.001 0.001 0.001" />
            </geometry>
        </collision>
    </link>
    <link name="bearing_axle_b">
        <inertial>
            <origin xyz="-0.14052464317965163 -0.49162303908152455 0.08152056799619971" rpy="0.0 -0.0 0.0" />
            <mass value="0.005178298951884693" />
            <inertia ixx="1.1373648643080506e-07" iyy="5.6838147068040065e-08" izz="1.137357654666367e-07" ixy="-2.5390606365463184e-12" iyz="-2.0357715822339265e-10" ixz="-8.850301676417704e-15" />
        </inertial>
        <visual name="bearing_axle_b_visual">
            <origin xyz="-0.2177162415047721 -0.6877435082145544 0.003596924154233605" rpy="1.5851203801543192 0.012681752394017524 2.3413869572187596e-05" />
            <geometry>
                <mesh filename="package://chronos_balance/urdf/meshes/bearing_axle_b.stl" scale="0.001 0.001 0.001" />
            </geometry>
        </visual>
        <collision name="bearing_axle_b_collision">
            <origin xyz="-0.2177162415047721 -0.6877435082145544 0.003596924154233605" rpy="1.5851203801543192 0.012681752394017524 2.3413869572187596e-05" />
            <geometry>
                <mesh filename="package://chronos_balance/urdf/meshes/bearing_axle_b.stl" scale="0.001 0.001 0.001" />
            </geometry>
        </collision>
    </link>
    <link name="outer_ball_bearing_b">
        <inertial>
            <origin xyz="4.891490581471203e-09 -0.00421890042207373 -3.024179980183561e-05" rpy="0.0 -0.0 0.0" />
            <mass value="0.009488893653327652" />
            <inertia ixx="5.478193891021492e-07" iyy="1.0829294816986422e-06" izz="5.47846882710543e-07" ixy="-2.8396849123153835e-13" iyz="3.835261727732509e-09" ixz="-5.358391020278504e-15" />
        </inertial>
        <visual name="outer_ball_bearing_b_visual">
            <origin xyz="0.22701738986697606 -0.05371551062601961 -0.29903433128328233" rpy="1.5706697301302137 -0.01983107811797458 1.5709572065323008" />
            <geometry>
                <mesh filename="package://chronos_balance/urdf/meshes/outer_ball_bearing_b.stl" scale="0.001 0.001 0.001" />
            </geometry>
        </visual>
        <collision name="outer_ball_bearing_b_collision">
            <origin xyz="0.22701738986697606 -0.05371551062601961 -0.29903433128328233" rpy="1.5706697301302137 -0.01983107811797458 1.5709572065323008" />
            <geometry>
                <mesh filename="package://chronos_balance/urdf/meshes/outer_ball_bearing_b.stl" scale="0.001 0.001 0.001" />
            </geometry>
        </collision>
    </link>
    <link name="base_link">
        <inertial>
            <origin xyz="-0.011778417044754857 0.0015000000000003064 -0.040835753340741555" rpy="0.0 0.0 0.0" />
            <mass value="0.26579790915917245" />
            <inertia ixx="0.0001293554926805798" iyy="0.0006414469757224287" izz="0.000512490179905589" ixy="-7.238745221596476e-18" iyz="-8.823965728021674e-18" ixz="2.4726794891313597e-07" />
        </inertial>
        <visual name="base_link_visual">
            <origin xyz="0.0 0.0 0.0" rpy="0.0 0.0 0.0" />
            <geometry>
                <mesh filename="package://chronos_balance/urdf/meshes/base_link.stl" scale="0.001 0.001 0.001" />
            </geometry>
        </visual>
        <collision name="base_link_collision">
            <origin xyz="0.0 0.0 0.0" rpy="0.0 0.0 0.0" />
            <geometry>
                <mesh filename="package://chronos_balance/urdf/meshes/base_link.stl" scale="0.001 0.001 0.001" />
            </geometry>
        </collision>
    </link>
    <link name="motor_upper_leg_below_a-v1">
        <inertial>
            <origin xyz="0.017691234082444947 0.019036803760310583 -0.017139907953109976" rpy="0.0 5.010199883009187e-19 0.0" />
            <mass value="0.5660198700931592" />
            <inertia ixx="0.00023301596671950378" iyy="0.0001323316431234326" izz="0.00019475274307636245" ixy="-1.0575967679307387e-06" iyz="-7.1479090506175e-06" ixz="3.551466904712038e-07" />
        </inertial>
        <visual name="motor_upper_leg_below_a-v1_visual">
            <origin xyz="0.24287888255392795 0.30046305471202356 0.06109852436183258" rpy="2.348431397848506 1.5529697431953742 -0.7914523380800792" />
            <geometry>
                <mesh filename="package://chronos_balance/urdf/meshes/motor_upper_leg_below_a-v1.stl" scale="0.001 0.001 0.001" />
            </geometry>
        </visual>
        <collision name="motor_upper_leg_below_a-v1_collision">
            <origin xyz="0.24287888255392795 0.30046305471202356 0.06109852436183258" rpy="2.348431397848506 1.5529697431953742 -0.7914523380800792" />
            <geometry>
                <mesh filename="package://chronos_balance/urdf/meshes/motor_upper_leg_below_a-v1.stl" scale="0.001 0.001 0.001" />
            </geometry>
        </collision>
    </link>
    <link name="motor_upper_leg_below-v1">
        <inertial>
            <origin xyz="-0.017278127015459114 0.019408472291641096 0.01714450156110683" rpy="0.0 4.548566926755592e-19 0.0" />
            <mass value="0.5660198700931592" />
            <inertia ixx="0.00023301491566552417" iyy="0.00013232928904066923" izz="0.0001947561482367705" ixy="-1.1065175142334538e-06" iyz="7.123732271037214e-06" ixz="5.084925665438881e-07" />
        </inertial>
        <visual name="motor_upper_leg_below-v1_visual">
            <origin xyz="-0.23636631375392056 0.30562721726710373 -0.06102621224031463" rpy="-0.8025805660262727 -1.5528010361249065 -2.362212098553636" />
            <geometry>
                <mesh filename="package://chronos_balance/urdf/meshes/motor_upper_leg_below-v1.stl" scale="0.001 0.001 0.001" />
            </geometry>
        </visual>
        <collision name="motor_upper_leg_below-v1_collision">
            <origin xyz="-0.23636631375392056 0.30562721726710373 -0.06102621224031463" rpy="-0.8025805660262727 -1.5528010361249065 -2.362212098553636" />
            <geometry>
                <mesh filename="package://chronos_balance/urdf/meshes/motor_upper_leg_below-v1.stl" scale="0.001 0.001 0.001" />
            </geometry>
        </collision>
    </link>
    <link name="battery_bracket_upper-v1">
        <inertial>
            <origin xyz="-0.0026860232123393857 -0.0011712304173419597 3.40377435232675e-05" rpy="-2.710505431213761e-20 7.199780051661553e-20 0.0" />
            <mass value="0.022654809940963756" />
            <inertia ixx="6.496563186817331e-06" iyy="4.648538568912141e-06" izz="2.1701015532442066e-06" ixy="-1.1131713388543715e-07" iyz="1.3684000673337372e-09" ixz="-5.480856345405827e-08" />
        </inertial>
        <visual name="battery_bracket_upper-v1_visual">
            <origin xyz="0.16066059481160166 -0.38057503030103224 -0.03400139600931688" rpy="-0.8056793539220193 -1.552745292101945 0.7789010828665305" />
            <geometry>
                <mesh filename="package://chronos_balance/urdf/meshes/battery_bracket_upper-v1.stl" scale="0.001 0.001 0.001" />
            </geometry>
        </visual>
        <collision name="battery_bracket_upper-v1_collision">
            <origin xyz="0.16066059481160166 -0.38057503030103224 -0.03400139600931688" rpy="-0.8056793539220193 -1.552745292101945 0.7789010828665305" />
            <geometry>
                <mesh filename="package://chronos_balance/urdf/meshes/battery_bracket_upper-v1.stl" scale="0.001 0.001 0.001" />
            </geometry>
        </collision>
    </link>
    <link name="battery_bracket_upper_a">
        <inertial>
            <origin xyz="0.004657158578638025 0.012174772746858409 -0.01694258331189733" rpy="0.0 -2.642742795433417e-19 0.0" />
            <mass value="0.022654809940963756" />
            <inertia ixx="6.500980257408275e-06" iyy="4.644120816654885e-06" izz="2.170102236158547e-06" ixy="6.485422537830163e-08" iyz="7.798723044792599e-10" ixz="5.486346750767736e-08" />
        </inertial>
        <visual name="battery_bracket_upper_a_visual">
            <origin xyz="0.17746196453907417 0.3873543180054638 0.01721264459329362" rpy="2.34843138640462 1.5529697431267189 -0.7914523342732414" />
            <geometry>
                <mesh filename="package://chronos_balance/urdf/meshes/battery_bracket_upper_a.stl" scale="0.001 0.001 0.001" />
            </geometry>
        </visual>
        <collision name="battery_bracket_upper_a_collision">
            <origin xyz="0.17746196453907417 0.3873543180054638 0.01721264459329362" rpy="2.34843138640462 1.5529697431267189 -0.7914523342732414" />
            <geometry>
                <mesh filename="package://chronos_balance/urdf/meshes/battery_bracket_upper_a.stl" scale="0.001 0.001 0.001" />
            </geometry>
        </collision>
    </link>
    <link name="ball_bearing-v1">
        <inertial>
            <origin xyz="2.3434181617467687e-05 3.460366830410067e-08 0.0018498470893143805" rpy="2.7105054312137605e-20 -1.568281501841337e-18 -1.734723475976807e-18" />
            <mass value="0.0024636840828348864" />
            <inertia ixx="3.053109427343083e-08" iyy="3.0527098744117767e-08" izz="5.5428897036245675e-08" ixy="5.305137460879895e-15" iyz="4.184394694789249e-13" ixz="3.154110845987728e-10" />
        </inertial>
        <visual name="ball_bearing-v1_visual">
            <origin xyz="0.015212826094438832 -0.019837663457371237 -0.00019235979562488126" rpy="0.0001192998809375461 0.012664969323934256 0.010746294543962195" />
            <geometry>
                <mesh filename="package://chronos_balance/urdf/meshes/ball_bearing-v1.stl" scale="0.001 0.001 0.001" />
            </geometry>
        </visual>
        <collision name="ball_bearing-v1_collision">
            <origin xyz="0.015212826094438832 -0.019837663457371237 -0.00019235979562488126" rpy="0.0001192998809375461 0.012664969323934256 0.010746294543962195" />
            <geometry>
                <mesh filename="package://chronos_balance/urdf/meshes/ball_bearing-v1.stl" scale="0.001 0.001 0.001" />
            </geometry>
        </collision>
    </link>
    <link name="outer_ball_bearing2-v1">
        <inertial>
            <origin xyz="-3.063890323645069e-05 4.43493178536869e-08 0.002418807669249761" rpy="0.0 -1.7237120476625012e-19 0.0" />
            <mass value="0.009488893653327652" />
            <inertia ixx="5.47905234351098e-07" iyy="5.478193890718014e-07" izz="1.0828711297087474e-06" ixy="-1.106978423404504e-13" iyz="8.991427075370477e-12" ixz="-6.777070031044458e-09" />
        </inertial>
        <visual name="outer_ball_bearing2-v1_visual">
            <origin xyz="0.3031636493269004 0.21996716637551766 0.05789800956325543" rpy="0.012611127342414857 1.5706770364813343 1.5601280032621327" />
            <geometry>
                <mesh filename="package://chronos_balance/urdf/meshes/outer_ball_bearing2-v1.stl" scale="0.001 0.001 0.001" />
            </geometry>
        </visual>
        <collision name="outer_ball_bearing2-v1_collision">
            <origin xyz="0.3031636493269004 0.21996716637551766 0.05789800956325543" rpy="0.012611127342414857 1.5706770364813343 1.5601280032621327" />
            <geometry>
                <mesh filename="package://chronos_balance/urdf/meshes/outer_ball_bearing2-v1.stl" scale="0.001 0.001 0.001" />
            </geometry>
        </collision>
    </link>
    <link name="outer_ball_bearing1-v1">
        <inertial>
            <origin xyz="3.063966363981763e-05 3.89589444438343e-08 0.0024188059320553634" rpy="2.7105054312137605e-20 -1.568281501841337e-18 -1.734723475976807e-18" />
            <mass value="0.009488893653327652" />
            <inertia ixx="5.479052276503264e-07" iyy="5.478193959055367e-07" izz="1.082871129748172e-06" ixy="1.1233666062926117e-13" iyz="8.9898701775343e-12" ixz="6.777071316747202e-09" />
        </inertial>
        <visual name="outer_ball_bearing1-v1_visual">
            <origin xyz="0.1419964412407383 -0.3474922870241028 0.05226905764775044" rpy="2.494986395255016 1.5552818788085012 2.2313202144471984" />
            <geometry>
                <mesh filename="package://chronos_balance/urdf/meshes/outer_ball_bearing1-v1.stl" scale="0.001 0.001 0.001" />
            </geometry>
        </visual>
        <collision name="outer_ball_bearing1-v1_collision">
            <origin xyz="0.1419964412407383 -0.3474922870241028 0.05226905764775044" rpy="2.494986395255016 1.5552818788085012 2.2313202144471984" />
            <geometry>
                <mesh filename="package://chronos_balance/urdf/meshes/outer_ball_bearing1-v1.stl" scale="0.001 0.001 0.001" />
            </geometry>
        </collision>
    </link>
    <link name="left_leg_bearing_axle-v1">
        <inertial>
            <origin xyz="0.004423650154264571 -6.8471434033767765e-09 7.867929689098219e-08" rpy="0.0 -0.0 -1.9370958201349979e-63" />
            <mass value="0.005178298951884693" />
            <inertia ixx="5.6837418580674175e-08" iyy="1.1373649381779977e-07" izz="1.1373648663783351e-07" ixy="4.279061371731245e-14" iyz="7.902207534160605e-16" ixz="-9.555665720500932e-13" />
        </inertial>
        <visual name="left_leg_bearing_axle-v1_visual">
            <origin xyz="-0.19197647215812524 -0.0711071729307608 -0.08285303485175746" rpy="1.5814769665478925 -1.4817406294273776 -1.5707303770522674" />
            <geometry>
                <mesh filename="package://chronos_balance/urdf/meshes/left_leg_bearing_axle-v1.stl" scale="0.001 0.001 0.001" />
            </geometry>
        </visual>
        <collision name="left_leg_bearing_axle-v1_collision">
            <origin xyz="-0.19197647215812524 -0.0711071729307608 -0.08285303485175746" rpy="1.5814769665478925 -1.4817406294273776 -1.5707303770522674" />
            <geometry>
                <mesh filename="package://chronos_balance/urdf/meshes/left_leg_bearing_axle-v1.stl" scale="0.001 0.001 0.001" />
            </geometry>
        </collision>
    </link>
    <link name="upper_leg_a-v1">
        <inertial>
            <origin xyz="0.010720585634635179 0.045406697564111025 -0.024454780783129758" rpy="-2.710505431213761e-20 1.6623021589865644e-18 0.0" />
            <mass value="0.23053636913542203" />
            <inertia ixx="0.00018919374299832404" iyy="0.00012216853051605136" izz="0.00010440722465114722" ixy="6.849190985547401e-07" iyz="6.892408306887299e-07" ixz="1.0295360664338547e-06" />
        </inertial>
        <visual name="upper_leg_a-v1_visual">
            <origin xyz="-0.21546422168545498 0.2967536170145006 -0.082472713858456" rpy="2.3609826418074276 1.5527452921020761 -0.77890108285942" />
            <geometry>
                <mesh filename="package://chronos_balance/urdf/meshes/upper_leg_a-v1.stl" scale="0.001 0.001 0.001" />
            </geometry>
        </visual>
        <collision name="upper_leg_a-v1_collision">
            <origin xyz="-0.21546422168545498 0.2967536170145006 -0.082472713858456" rpy="2.3609826418074276 1.5527452921020761 -0.77890108285942" />
            <geometry>
                <mesh filename="package://chronos_balance/urdf/meshes/upper_leg_a-v1.stl" scale="0.001 0.001 0.001" />
            </geometry>
        </collision>
    </link>
    <link name="upper_leg-v1">
        <inertial>
            <origin xyz="0.008118896294493113 0.04581836371514846 0.023781249790376578" rpy="0.0 -1.0545560193316039e-19 0.0" />
            <mass value="0.23053636913542203" />
            <inertia ixx="0.00018900652539572917" iyy="0.00012235653054343411" izz="0.00010440644222727695" ixy="3.6034387813374343e-06" iyz="7.236131992899462e-07" ixz="9.974616162021741e-07" />
        </inertial>
        <visual name="upper_leg-v1_visual">
            <origin xyz="-0.22881273015480502 0.28702875143566375 -0.03437263900275891" rpy="2.339164343875628 1.5523619102991872 -0.7570860185497665" />
            <geometry>
                <mesh filename="package://chronos_balance/urdf/meshes/upper_leg-v1.stl" scale="0.001 0.001 0.001" />
            </geometry>
        </visual>
        <collision name="upper_leg-v1_collision">
            <origin xyz="-0.22881273015480502 0.28702875143566375 -0.03437263900275891" rpy="2.339164343875628 1.5523619102991872 -0.7570860185497665" />
            <geometry>
                <mesh filename="package://chronos_balance/urdf/meshes/upper_leg-v1.stl" scale="0.001 0.001 0.001" />
            </geometry>
        </collision>
    </link>
    <link name="battery_support-v1">
        <inertial>
            <origin xyz="-2.559542737756715e-08 -0.0025924642007404586 0.00365791246677329" rpy="0.0 -0.0 5.293955920339378e-23" />
            <mass value="0.027891202513890205" />
            <inertia ixx="3.4753294932511132e-06" iyy="8.221972795232258e-06" izz="5.1384526668130255e-06" ixy="2.6285882296750196e-12" iyz="1.4395114906712448e-08" ixz="-9.735565900064584e-12" />
        </inertial>
        <visual name="battery_support-v1_visual">
            <origin xyz="-0.07502440230203654 -0.25110508695268347 0.2886943017642176" rpy="-1.574373934865192 0.012658611786868341 0.00011286496491905425" />
            <geometry>
                <mesh filename="package://chronos_balance/urdf/meshes/battery_support-v1.stl" scale="0.001 0.001 0.001" />
            </geometry>
        </visual>
        <collision name="battery_support-v1_collision">
            <origin xyz="-0.07502440230203654 -0.25110508695268347 0.2886943017642176" rpy="-1.574373934865192 0.012658611786868341 0.00011286496491905425" />
            <geometry>
                <mesh filename="package://chronos_balance/urdf/meshes/battery_support-v1.stl" scale="0.001 0.001 0.001" />
            </geometry>
        </collision>
    </link>
    <link name="leg_knee_motor_a">
        <inertial>
            <origin xyz="0.00897253868413248 -0.03071397310518922 -0.016751709877148375" rpy="0.0 -4.353749348887104e-19 0.0" />
            <mass value="0.5660198700847786" />
            <inertia ixx="0.0002325220535051531" iyy="0.00013263549536883667" izz="0.00019459064279429473" ixy="-5.730199292383312e-06" iyz="7.11009707748012e-06" ixz="-5.506192489121199e-08" />
        </inertial>
        <visual name="leg_knee_motor_a_visual">
            <origin xyz="0.22020414206340813 -0.24538829373385 -0.024526009693550163" rpy="2.3984510478935213 1.5534236113101028 2.327879285725305" />
            <geometry>
                <mesh filename="package://chronos_balance/urdf/meshes/leg_knee_motor_a.stl" scale="0.001 0.001 0.001" />
            </geometry>
        </visual>
        <collision name="leg_knee_motor_a_collision">
            <origin xyz="0.22020414206340813 -0.24538829373385 -0.024526009693550163" rpy="2.3984510478935213 1.5534236113101028 2.327879285725305" />
            <geometry>
                <mesh filename="package://chronos_balance/urdf/meshes/leg_knee_motor_a.stl" scale="0.001 0.001 0.001" />
            </geometry>
        </collision>
    </link>
    <link name="leg_knee_motor-v1">
        <inertial>
            <origin xyz="0.010830047907249991 0.03024572756970393 -0.01650189930230696" rpy="2.710505431213761e-20 4.336808689942018e-19 1.734723475976807e-18" />
            <mass value="0.5660198700847786" />
            <inertia ixx="0.0002328265668200208" iyy="0.00013231755819359775" izz="0.00019460406665643522" ixy="1.5245108104431518e-06" iyz="-7.028458691791745e-06" ixz="5.68217214395226e-07" />
        </inertial>
        <visual name="leg_knee_motor-v1_visual">
            <origin xyz="-0.21535186875306647 0.22909869808443234 -0.02447250997700903" rpy="2.360982641808556 1.5527452921020626 -0.7789010828586903" />
            <geometry>
                <mesh filename="package://chronos_balance/urdf/meshes/leg_knee_motor-v1.stl" scale="0.001 0.001 0.001" />
            </geometry>
        </visual>
        <collision name="leg_knee_motor-v1_collision">
            <origin xyz="-0.21535186875306647 0.22909869808443234 -0.02447250997700903" rpy="2.360982641808556 1.5527452921020626 -0.7789010828586903" />
            <geometry>
                <mesh filename="package://chronos_balance/urdf/meshes/leg_knee_motor-v1.stl" scale="0.001 0.001 0.001" />
            </geometry>
        </collision>
    </link>
    <link name="leg_ankle_motor_av1">
        <inertial>
            <origin xyz="0.0004875820137030118 -0.011281962361597531 0.025565572255754426" rpy="0.0 -1.212951180468158e-18 0.0" />
            <mass value="0.34532380048520933" />
            <inertia ixx="9.880925311860786e-05" iyy="6.120864278093158e-05" izz="8.180135779057755e-05" ixy="6.050836528758406e-07" iyz="3.0832822866534504e-06" ixz="-2.1394948559808741e-07" />
        </inertial>
        <visual name="leg_ankle_motor_av1_visual">
            <origin xyz="0.22399434921793235 0.0724303813636372 0.08780622760030964" rpy="-2.3390121479633543 -1.5528010352268495 -0.7793805058641321" />
            <geometry>
                <mesh filename="package://chronos_balance/urdf/meshes/leg_ankle_motor_av1.stl" scale="0.001 0.001 0.001" />
            </geometry>
        </visual>
        <collision name="leg_ankle_motor_av1_collision">
            <origin xyz="0.22399434921793235 0.0724303813636372 0.08780622760030964" rpy="-2.3390121479633543 -1.5528010352268495 -0.7793805058641321" />
            <geometry>
                <mesh filename="package://chronos_balance/urdf/meshes/leg_ankle_motor_av1.stl" scale="0.001 0.001 0.001" />
            </geometry>
        </collision>
    </link>
    <link name="leg_ankle_motor-v1">
        <inertial>
            <origin xyz="-0.0003617454082449001 0.011283417798743303 0.020216353709550692" rpy="0.0 1.3196773318222e-18 1.734723475976807e-18" />
            <mass value="0.34532380048520933" />
            <inertia ixx="9.881448642820737e-05" iyy="6.120360435303145e-05" izz="8.180116290856375e-05" ixy="4.1147521315842764e-07" iyz="-3.0849939907228233e-06" ixz="1.9809492912089104e-07" />
        </inertial>
        <visual name="leg_ankle_motor-v1_visual">
            <origin xyz="-0.22429654699345072 -0.07127913453822327 0.08245428624572769" rpy="-2.3402770141450566 -1.5528230064623743 2.358328619859058" />
            <geometry>
                <mesh filename="package://chronos_balance/urdf/meshes/leg_ankle_motor-v1.stl" scale="0.001 0.001 0.001" />
            </geometry>
        </visual>
        <collision name="leg_ankle_motor-v1_collision">
            <origin xyz="-0.22429654699345072 -0.07127913453822327 0.08245428624572769" rpy="-2.3402770141450566 -1.5528230064623743 2.358328619859058" />
            <geometry>
                <mesh filename="package://chronos_balance/urdf/meshes/leg_ankle_motor-v1.stl" scale="0.001 0.001 0.001" />
            </geometry>
        </collision>
    </link>
    <link name="Lower_Leg_v2-v1">
        <inertial>
            <origin xyz="0.0009273194073108115 -0.055801125792479866 0.02682103698661959" rpy="0.0 -4.3283383604694747e-19 -1.734723475976807e-18" />
            <mass value="0.3110955036381271" />
            <inertia ixx="0.0004447115363330255" iyy="0.0002043753639567613" izz="0.00030693128466132205" ixy="-4.645304887556617e-06" iyz="-7.67282249929655e-06" ixz="-2.138846178728944e-06" />
        </inertial>
        <visual name="Lower_Leg_v2-v1_visual">
            <origin xyz="0.22009156074525205 -0.19107892846621138 -0.0500428400039169" rpy="-0.8056793972092466 -1.552745291102488 0.7789011373852248" />
            <geometry>
                <mesh filename="package://chronos_balance/urdf/meshes/Lower_Leg_v2-v1.stl" scale="0.001 0.001 0.001" />
            </geometry>
        </visual>
        <collision name="Lower_Leg_v2-v1_collision">
            <origin xyz="0.22009156074525205 -0.19107892846621138 -0.0500428400039169" rpy="-0.8056793972092466 -1.552745291102488 0.7789011373852248" />
            <geometry>
                <mesh filename="package://chronos_balance/urdf/meshes/Lower_Leg_v2-v1.stl" scale="0.001 0.001 0.001" />
            </geometry>
        </collision>
    </link>
    <link name="biped_ankle_a-v1">
        <inertial>
            <origin xyz="4.32743924924317e-05 -0.04102455949580392 -0.018542638179065284" rpy="-1.734723475976807e-18 -3.3881317890172014e-21 5.293955920339377e-23" />
            <mass value="0.6890395194323967" />
            <inertia ixx="0.0011332506520755309" iyy="0.0004820597307631127" izz="0.0011647512583857563" ixy="4.595058415104515e-07" iyz="0.00016957786362236857" ixz="-3.4245123923740416e-07" />
        </inertial>
        <visual name="biped_ankle_a-v1_visual">
            <origin xyz="-0.17473511066555275 0.11811399967072692 0.08389774142919841" rpy="1.567218726194995 -0.012658611881238175 -0.00011286496294050455" />
            <geometry>
                <mesh filename="package://chronos_balance/urdf/meshes/biped_ankle_a-v1.stl" scale="0.001 0.001 0.001" />
            </geometry>
        </visual>
        <collision name="biped_ankle_a-v1_collision">
            <origin xyz="-0.17473511066555275 0.11811399967072692 0.08389774142919841" rpy="1.567218726194995 -0.012658611881238175 -0.00011286496294050455" />
            <geometry>
                <mesh filename="package://chronos_balance/urdf/meshes/biped_ankle_a-v1.stl" scale="0.001 0.001 0.001" />
            </geometry>
        </collision>
    </link>
    <link name="lower_leg_right-v1">
        <inertial>
            <origin xyz="-0.002186704786341949 -0.05577454893173167 -0.02680320974738825" rpy="0.0 -4.31563286626066e-19 -1.734723475976807e-18" />
            <mass value="0.31109549893505384" />
            <inertia ixx="0.0004438864298265911" iyy="0.0002052295769849327" izz="0.000306902161815737" ixy="-1.4906297546006467e-05" iyz="7.899388331646045e-06" ixz="-1.0046890722629312e-06" />
        </inertial>
        <visual name="lower_leg_right-v1_visual">
            <origin xyz="0.21274448277154268 -0.20052261884492356 0.04456684647623526" rpy="2.398450985536075 1.5534236103480974 2.327879226954329" />
            <geometry>
                <mesh filename="package://chronos_balance/urdf/meshes/lower_leg_right-v1.stl" scale="0.001 0.001 0.001" />
            </geometry>
        </visual>
        <collision name="lower_leg_right-v1_collision">
            <origin xyz="0.21274448277154268 -0.20052261884492356 0.04456684647623526" rpy="2.398450985536075 1.5534236103480974 2.327879226954329" />
            <geometry>
                <mesh filename="package://chronos_balance/urdf/meshes/lower_leg_right-v1.stl" scale="0.001 0.001 0.001" />
            </geometry>
        </collision>
    </link>
    <link name="leg_bearing_a-v1">
        <inertial>
            <origin xyz="-0.003952058781668555 -0.007642624156104549 0.015051393201372196" rpy="2.710505431213761e-20 4.2521053952165877e-19 -1.734723475976807e-18" />
            <mass value="0.01108393901132922" />
            <inertia ixx="2.3210634588244607e-06" iyy="1.7789905135168915e-06" izz="6.750674766504507e-07" ixy="-2.7960134097913905e-08" iyz="3.356197457843792e-10" ixz="-2.0852083478923675e-08" />
        </inertial>
        <visual name="leg_bearing_a-v1_visual">
            <origin xyz="-0.20642921777409526 0.07425866925030686 0.09282169366099212" rpy="0.8056793462866302 1.5527452921020382 -2.3626915707326" />
            <geometry>
                <mesh filename="package://chronos_balance/urdf/meshes/leg_bearing_a-v1.stl" scale="0.001 0.001 0.001" />
            </geometry>
        </visual>
        <collision name="leg_bearing_a-v1_collision">
            <origin xyz="-0.20642921777409526 0.07425866925030686 0.09282169366099212" rpy="0.8056793462866302 1.5527452921020382 -2.3626915707326" />
            <geometry>
                <mesh filename="package://chronos_balance/urdf/meshes/leg_bearing_a-v1.stl" scale="0.001 0.001 0.001" />
            </geometry>
        </collision>
    </link>
    <link name="leg_bearing_1-v1">
        <inertial>
            <origin xyz="-0.00378376943496594 0.011724100347529265 0.015048934979193582" rpy="-2.7105054312137605e-20 -1.2328564547286341e-18 -1.734723475976807e-18" />
            <mass value="0.01108393901132922" />
            <inertia ixx="2.3219618780004074e-06" iyy="1.7780919312612222e-06" izz="6.750676397734933e-07" ixy="1.7137220155082207e-08" iyz="-2.3559468364161226e-10" ixz="-2.0864211485618966e-08" />
        </inertial>
        <visual name="leg_bearing_1-v1_visual">
            <origin xyz="-0.20975676483425773 -0.0661083328595133 -0.05754775169575918" rpy="-0.7762463049369677 -1.5528230064623931 0.783264033729696" />
            <geometry>
                <mesh filename="package://chronos_balance/urdf/meshes/leg_bearing_1-v1.stl" scale="0.001 0.001 0.001" />
            </geometry>
        </visual>
        <collision name="leg_bearing_1-v1_collision">
            <origin xyz="-0.20975676483425773 -0.0661083328595133 -0.05754775169575918" rpy="-0.7762463049369677 -1.5528230064623931 0.783264033729696" />
            <geometry>
                <mesh filename="package://chronos_balance/urdf/meshes/leg_bearing_1-v1.stl" scale="0.001 0.001 0.001" />
            </geometry>
        </collision>
    </link>
    <link name="foot_motor-v1">
        <inertial>
            <origin xyz="-0.017300662687734187 0.017756737199257112 -0.02453055361474384" rpy="0.0 3.3881317890172014e-21 5.293955920339377e-23" />
            <mass value="0.5660198701230377" />
            <inertia ixx="0.00023301067003636392" iyy="0.00019405625707047392" izz="0.00013264704652086488" ixy="7.877726672104125e-08" iyz="8.13100750246553e-06" ixz="-2.7349878712121574e-08" />
        </inertial>
        <visual name="foot_motor-v1_visual">
            <origin xyz="-0.09250227558935471 0.2873954033138025 -0.11459908792188844" rpy="1.5759460750761745 -0.012657138316090706 -0.00022338373476473567" />
            <geometry>
                <mesh filename="package://chronos_balance/urdf/meshes/foot_motor-v1.stl" scale="0.001 0.001 0.001" />
            </geometry>
        </visual>
        <collision name="foot_motor-v1_collision">
            <origin xyz="-0.09250227558935471 0.2873954033138025 -0.11459908792188844" rpy="1.5759460750761745 -0.012657138316090706 -0.00022338373476473567" />
            <geometry>
                <mesh filename="package://chronos_balance/urdf/meshes/foot_motor-v1.stl" scale="0.001 0.001 0.001" />
            </geometry>
        </collision>
    </link>
    <link name="foot_motor_a-v1">
        <inertial>
            <origin xyz="-0.017300662246572385 0.017541991439080126 -0.02468458144223866" rpy="0.0 3.3881317890172014e-21 0.0" />
            <mass value="0.5660198701230377" />
            <inertia ixx="0.0002330106700240441" iyy="0.00019419348632092055" izz="0.0001325098172756038" ixy="7.85375440193773e-08" iyz="7.593899636504136e-06" ixz="-2.8036059983110235e-08" />
        </inertial>
        <visual name="foot_motor_a-v1_visual">
            <origin xyz="-0.09250228838456925 0.28638440008328636 -0.11710269903754016" rpy="1.5672187261949673 -0.012658611881251683 -0.00011286496293184014" />
            <geometry>
                <mesh filename="package://chronos_balance/urdf/meshes/foot_motor_a-v1.stl" scale="0.001 0.001 0.001" />
            </geometry>
        </visual>
        <collision name="foot_motor_a-v1_collision">
            <origin xyz="-0.09250228838456925 0.28638440008328636 -0.11710269903754016" rpy="1.5672187261949673 -0.012658611881251683 -0.00011286496293184014" />
            <geometry>
                <mesh filename="package://chronos_balance/urdf/meshes/foot_motor_a-v1.stl" scale="0.001 0.001 0.001" />
            </geometry>
        </collision>
    </link>
    <link name="down_foot_bearing_a-v1">
        <inertial>
            <origin xyz="0.0039520413331809575 0.007642586108461261 -0.015051391587923879" rpy="2.710505431213761e-20 4.2521053952165877e-19 -1.734723475976807e-18" />
            <mass value="0.011084011226936016" />
            <inertia ixx="2.3210862549763342e-06" iyy="1.7790107625265105e-06" izz="6.750715734974079e-07" ixy="-2.7960946154754826e-08" iyz="3.356353305612868e-10" ixz="-2.0852315395261656e-08" />
        </inertial>
        <visual name="down_foot_bearing_a-v1_visual">
            <origin xyz="0.2064292135716537 -0.07425866976911027 -0.0928216922917343" rpy="-0.8056793462864452 -1.55274529210204 0.7789010828572976" />
            <geometry>
                <mesh filename="package://chronos_balance/urdf/meshes/down_foot_bearing_a-v1.stl" scale="0.001 0.001 0.001" />
            </geometry>
        </visual>
        <collision name="down_foot_bearing_a-v1_collision">
            <origin xyz="0.2064292135716537 -0.07425866976911027 -0.0928216922917343" rpy="-0.8056793462864452 -1.55274529210204 0.7789010828572976" />
            <geometry>
                <mesh filename="package://chronos_balance/urdf/meshes/down_foot_bearing_a-v1.stl" scale="0.001 0.001 0.001" />
            </geometry>
        </collision>
    </link>
    <link name="down_foot_bearing-v1">
        <inertial>
            <origin xyz="0.003885193749798219 0.007678439338056542 -0.015050548582705102" rpy="-2.7105054312137605e-20 -1.2328564547286341e-18 -1.734723475976807e-18" />
            <mass value="0.011084011226936016" />
            <inertia ixx="2.3215329018486927e-06" iyy="1.7785640419832857e-06" izz="6.750716471671964e-07" ixy="-2.3224499454402e-08" iyz="2.7564961500277195e-10" ixz="-2.0858052041839868e-08" />
        </inertial>
        <visual name="down_foot_bearing-v1_visual">
            <origin xyz="0.20706926581311197 -0.0724443189922343 -0.09282983323413374" rpy="-0.8013156394430829 -1.5528230064623938 0.7832640337296818" />
            <geometry>
                <mesh filename="package://chronos_balance/urdf/meshes/down_foot_bearing-v1.stl" scale="0.001 0.001 0.001" />
            </geometry>
        </visual>
        <collision name="down_foot_bearing-v1_collision">
            <origin xyz="0.20706926581311197 -0.0724443189922343 -0.09282983323413374" rpy="-0.8013156394430829 -1.5528230064623938 0.7832640337296818" />
            <geometry>
                <mesh filename="package://chronos_balance/urdf/meshes/down_foot_bearing-v1.stl" scale="0.001 0.001 0.001" />
            </geometry>
        </collision>
    </link>
    <link name="anklle_joint_axle-v1">
        <inertial>
            <origin xyz="2.3282586525397166e-09 -0.0044235285716936095 -3.170080444852896e-05" rpy="0.0 -0.0 0.0" />
            <mass value="0.005178298951884693" />
            <inertia ixx="1.1373648654232858e-07" iyy="5.6840341303855015e-08" izz="1.1373357114436375e-07" ixy="3.01312593038746e-14" iyz="-4.07788646078693e-10" ixz="2.608141023884993e-16" />
        </inertial>
        <visual name="anklle_joint_axle-v1_visual">
            <origin xyz="0.07520130420082549 0.1914056376893608 0.0805262123557655" rpy="-1.5887093196411746 0.01265893671710861 3.1415251109056106" />
            <geometry>
                <mesh filename="package://chronos_balance/urdf/meshes/anklle_joint_axle-v1.stl" scale="0.001 0.001 0.001" />
            </geometry>
        </visual>
        <collision name="anklle_joint_axle-v1_collision">
            <origin xyz="0.07520130420082549 0.1914056376893608 0.0805262123557655" rpy="-1.5887093196411746 0.01265893671710861 3.1415251109056106" />
            <geometry>
                <mesh filename="package://chronos_balance/urdf/meshes/anklle_joint_axle-v1.stl" scale="0.001 0.001 0.001" />
            </geometry>
        </collision>
    </link>
    <link name="left_leg_bearing_axle_c-v1">
        <inertial>
            <origin xyz="6.823587028748079e-09 -0.004423090934038001 -7.030510490973807e-05" rpy="0.0 -3.3881317890172014e-21 0.0" />
            <mass value="0.005178298951884693" />
            <inertia ixx="1.1373648655870318e-07" iyy="5.6851790749537375e-08" izz="1.137221216877616e-07" ixy="2.7211592581647547e-14" iyz="-9.041886212226218e-10" ixz="2.0084197120768921e-16" />
        </inertial>
        <visual name="left_leg_bearing_axle_c-v1_visual">
            <origin xyz="0.07718099678182877 0.19318091625760825 -0.07416231996092655" rpy="1.5656471521072177 0.012657858646206265 3.141414587571895" />
            <geometry>
                <mesh filename="package://chronos_balance/urdf/meshes/left_leg_bearing_axle_c-v1.stl" scale="0.001 0.001 0.001" />
            </geometry>
        </visual>
        <collision name="left_leg_bearing_axle_c-v1_collision">
            <origin xyz="0.07718099678182877 0.19318091625760825 -0.07416231996092655" rpy="1.5656471521072177 0.012657858646206265 3.141414587571895" />
            <geometry>
                <mesh filename="package://chronos_balance/urdf/meshes/left_leg_bearing_axle_c-v1.stl" scale="0.001 0.001 0.001" />
            </geometry>
        </collision>
    </link>
    <link name="biped_ankle-v1">
        <inertial>
            <origin xyz="4.326762577916199e-05 -0.04086117768293805 -0.018899930842515556" rpy="-1.734723475976807e-18 -0.0 1.0587911840678754e-22" />
            <mass value="0.6890395194323967" />
            <inertia ixx="0.001133250652120084" iyy="0.0004791521763512844" izz="0.001167658812751623" ixy="4.624442864235984e-07" iyz="0.00016359472862641772" ixz="-3.3841968413156285e-07" />
        </inertial>
        <visual name="biped_ankle-v1_visual">
            <origin xyz="-0.17473510862762454 0.11737738095862732 0.0849252781611178" rpy="1.5759460750762022 -0.012657138316077163 -0.00022338373477160425" />
            <geometry>
                <mesh filename="package://chronos_balance/urdf/meshes/biped_ankle-v1.stl" scale="0.001 0.001 0.001" />
            </geometry>
        </visual>
        <collision name="biped_ankle-v1_collision">
            <origin xyz="-0.17473510862762454 0.11737738095862732 0.0849252781611178" rpy="1.5759460750762022 -0.012657138316077163 -0.00022338373477160425" />
            <geometry>
                <mesh filename="package://chronos_balance/urdf/meshes/biped_ankle-v1.stl" scale="0.001 0.001 0.001" />
            </geometry>
        </collision>
    </link>
    <link name="ankle_joint_ring1_b">
        <inertial>
            <origin xyz="-4.6578660750640215e-09 -0.0013809598868452966 -9.90176673836274e-06" rpy="0.0 3.3881317890172014e-21 -5.293955920339377e-23" />
            <mass value="0.009488893653333197" />
            <inertia ixx="5.478193828547101e-07" iyy="1.0829294823278003e-06" izz="5.478468862566765e-07" ixy="2.8410729501794574e-13" iyz="3.835264122850228e-09" ixz="4.65095597770928e-16" />
        </inertial>
        <visual name="ankle_joint_ring1_b_visual">
            <origin xyz="-0.07520151702095146 -0.20303986370218796 0.07769911718807664" rpy="-1.574373927394792 0.012658611881250727 0.00011286496295004399" />
            <geometry>
                <mesh filename="package://chronos_balance/urdf/meshes/ankle_joint_ring1_b.stl" scale="0.001 0.001 0.001" />
            </geometry>
        </visual>
        <collision name="ankle_joint_ring1_b_collision">
            <origin xyz="-0.07520151702095146 -0.20303986370218796 0.07769911718807664" rpy="-1.574373927394792 0.012658611881250727 0.00011286496295004399" />
            <geometry>
                <mesh filename="package://chronos_balance/urdf/meshes/ankle_joint_ring1_b.stl" scale="0.001 0.001 0.001" />
            </geometry>
        </collision>
    </link>

    <link name="ankle_joint_ring1_a">
        <inertial>
            <origin xyz="1.4234482570429918e-09 -0.001380823781779803 -2.194486876580637e-05" rpy="0.0 -0.0 0.0" />
            <mass value="0.009488893653333197" />
            <inertia ixx="5.47819382851798e-07" iyy="1.0828217998408907e-06" izz="5.479545687339694e-07" ixy="2.565893753145521e-13" iyz="8.503921384183353e-09" ixz="2.502286137981435e-15" />
        </inertial>
        <visual name="ankle_joint_ring1_a_visual">
            <origin xyz="-0.07520150106275726 -0.2037101836872654 0.07592433035705219" rpy="-1.5656465785135842 0.012657138316089762 0.00022338373478500507" />
            <geometry>
                <mesh filename="package://chronos_balance/urdf/meshes/ankle_joint_ring1_a.stl" scale="0.001 0.001 0.001" />
            </geometry>
        </visual>
        <collision name="ankle_joint_ring1_a_collision">
            <origin xyz="-0.07520150106275726 -0.2037101836872654 0.07592433035705219" rpy="-1.5656465785135842 0.012657138316089762 0.00022338373478500507" />
            <geometry>
                <mesh filename="package://chronos_balance/urdf/meshes/ankle_joint_ring1_a.stl" scale="0.001 0.001 0.001" />
            </geometry>
        </collision>
    </link>
    <gazebo reference="base_link">
  <sensor name="imu_sensor" type="imu">
    <always_on>true</always_on>
    <update_rate>100.0</update_rate>
    <visualize>false</visualize>
    <plugin name="imu_plugin" filename="libgazebo_ros_imu_sensor.so">
      <ros>
        <namespace>/</namespace>
        <remapping>~/out:=imu/data</remapping>
      </ros>
      <frameName>base_link</frameName>
    </plugin>
  </sensor>
</gazebo>

    <joint name="motor_mx2R_Rigid_1" type="fixed">
        <origin xyz="0.31634176000000724 -0.13368617000000002 -0.5002055100000001" rpy="-1.5707963267948966 -7.173782711359874e-50 -2.3822801641527197e-21" />
        <parent link="motor_mx2R" />
        <child link="motor_bracket_a" />
    </joint>
    <joint name="motor_mx2L_Rigid_2" type="fixed">
        <origin xyz="0.14308481000000722 -0.13367078000000004 -0.5013202800000002" rpy="-1.5707963267948966 -7.173782711359874e-50 -2.3822801641527197e-21" />
        <parent link="motor_mx2L" />
        <child link="motor_bracket_b" />
    </joint>
    <joint name="motor_bracket_b_Rigid_9" type="fixed">
        <origin xyz="-0.0025617799999999935 -0.03804556000000002 -0.03306877999999998" rpy="0.0 -0.0 0.0" />
        <parent link="motor_bracket_b" />
        <child link="bearing_axle_b" />
    </joint>
    <joint name="motor_bracket_b_Rigid_10" type="fixed">
        <origin xyz="-0.14308662 -0.5310922400000001 0.04844670000000001" rpy="-0.010745583736695647 -2.2658692151483496e-05 -3.1415924100995474" />
        <parent link="motor_bracket_b" />
        <child link="outer_ball_bearing_b" />
    </joint>
    <joint name="base_link_Rigid_14" type="fixed">
        <origin xyz="0.02850322032569581 0.0029999996388005456 -0.05763786138376755" rpy="3.1380141847375884 -2.1969872416418803e-05 3.1415758568736476" />
        <parent link="base_link" />
        <child link="motor_mx2R" />
    </joint>
    <joint name="motor_bracket_b_Rigid-20" type="fixed">
        <origin xyz="-0.12808629 -0.44113745000000004 0.05230337000000002" rpy="3.1308470698530995 -2.2658692150262864e-05 -3.1415924100995474" />
        <parent link="motor_bracket_b" />
        <child link="motor_upper_a" />
    </joint>
    <joint name="motor_bracket_a_Rigid-21" type="fixed">
        <origin xyz="-0.30134324 -0.44002268 0.05231876" rpy="3.1308470698530995 -2.265869215026284e-05 -3.1415924100995474" />
        <parent link="motor_bracket_a" />
        <child link="motor_upper_b" />
    </joint>
    <joint name="outer_ball_bearing_Rigid-25" type="fixed">
        <origin xyz="9.382902597110388e-09 -0.0037998967525867755 -2.723289540494278e-05" rpy="1.5711138803812132 -0.02327809651477799 1.5581273882942754" />
        <parent link="outer_ball_bearing" />
        <child link="battery_bracket_upper-v1" />
    </joint>
    <joint name="battery_bracket_upper-v1_Rigid-26" type="fixed">
        <origin xyz="-0.0066059951352143995 0.011111640148074855 0.017084852751183315" rpy="3.141275192647384 -3.979157800939441e-06 -0.025067331155276033" />
        <parent link="battery_bracket_upper-v1" />
        <child link="motor_upper_leg_below-v1" />
    </joint>
    <joint name="motor_upper_leg_below-v1_Rigid-28" type="fixed">
        <origin xyz="-0.01718379702359286 0.004216449971184702 -0.005218125094826576" rpy="-3.141592653493228 -1.0674540949513062e-13 -7.624181576001976e-09" />
        <parent link="motor_upper_leg_below-v1" />
        <child link="ball_bearing-v1" />
    </joint>
    <joint name="motor_upper_leg_below-v1_Revolute-31" type="revolute">
        <origin xyz="-0.01720279373286182 0.00421646996961357 -0.003718245391304613" rpy="-3.141592653493228 -1.0674540949513062e-13 -7.624181576001976e-09" />
        <parent link="motor_upper_leg_below-v1" />
        <child link="outer_ball_bearing1-v1" />
        <axis xyz="0.01266542673166224 1.7011198854498433e-05 0.9999197902663612" />
        <limit lower="-0.785398" upper="0.785398" effort="1000000" velocity="1000000" />
    </joint>
    <joint name="ball_bearing-v1_Rigid-32" type="fixed">
        <origin xyz="4.686828892033645e-05 7.011984433091812e-08 0.00369970314533159" rpy="-1.583330994048457 1.5581313482598826 -3.141592653589793" />
        <parent link="ball_bearing-v1" />
        <child link="left_leg_bearing_axle-v1" />
    </joint>
    <joint name="outer_ball_bearing1-v1_Rigid-34" type="fixed">
        <origin xyz="-0.010942546517095338 0.00043082198602650834 0.00393888930986396" rpy="-3.141275192743919 -3.979155260152159e-06 0.025067323531094945" />
        <parent link="outer_ball_bearing1-v1" />
        <child link="upper_leg-v1" />
    </joint>
    <joint name="motor_upper_a_Rigid-35" type="fixed">
        <origin xyz="0.015052597863953734 -0.03553006036502085 0.004066191936267849" rpy="-1.864827736675068e-15 -8.877776037094845e-15 -4.224576824430823e-20" />
        <parent link="motor_upper_a" />
        <child link="battery_support-v1" />
    </joint>
    <joint name="battery_support-v1_Rigid-36" type="fixed">
        <origin xyz="-0.016999939570957724 -0.007172362648864041 -0.011051782994574459" rpy="1.5707963267948315 -0.0017892346412206907 -1.5581313685301181" />
        <parent link="battery_support-v1" />
        <child link="motor_upper_leg_below_a-v1" />
    </joint>
    <joint name="base_link_Rigid-44" type="fixed">
        <origin xyz="-0.05687877970692431 0.0030000004769613754 -0.05763786069313166" rpy="3.1380141847375884 -2.1969872416418803e-05 3.1415758568736476" />
        <parent link="base_link" />
        <child link="motor_mx2L" />
    </joint>
    <joint name="leg_ankle_motor-v1_Rigid-51" type="fixed">
        <origin xyz="-0.01566589492755613 0.029388997094438273 0.0353039184472272" rpy="-3.141592653589793 -1.0802041769744641e-16 -3.2959746043559335e-16" />
        <parent link="leg_ankle_motor-v1" />
        <child link="leg_bearing_1-v1" />
    </joint>
    <joint name="lower_leg_right-v1_Revolute-69" type="revolute">
        <origin xyz="-0.007025839637519056 -0.11588741449776781 -0.007356660273046174" rpy="-3.1415926535897833 -2.5688076188081935e-14 7.877552776758277e-13" />
        <parent link="lower_leg_right-v1" />
        <child link="leg_ankle_motor-v1" />
        <axis xyz="-0.012665852865054167 1.6986130176459493e-05 0.9999197848691024" />
        <limit lower="-0.523599" upper="0.523599" effort="1000000" velocity="1000000" />
    </joint>
    <joint name="motor_bracket_a_Rigid-72" type="fixed">
        <origin xyz="-0.31634357 -0.52997746 0.048462089999999985" rpy="-0.010745583736695643 -2.2658692151483472e-05 -3.1415924100995474" />
        <parent link="motor_bracket_a" />
        <child link="outer_ball_bearing" />
    </joint>
    <joint name="upper_leg-v1_Rigid-73" type="fixed">
        <origin xyz="-0.003913009475404792 0.06818683061061023 0.006217911818934532" rpy="3.1415926535897873 2.4939637452371562e-14 4.784922458256346e-13" />
        <parent link="upper_leg-v1" />
        <child link="leg_knee_motor_a" />
    </joint>
    <joint name="leg_knee_motor_a_Revolute-74" type="revolute">
        <origin xyz="0.008414144226608756 -0.04587580167002472 0.010895071675050296" rpy="3.2526065174565143e-19 3.0336485005912774e-18 1.7347234759768075e-18" />
        <parent link="leg_knee_motor_a" />
        <child link="lower_leg_right-v1" />
        <axis xyz="0.012665852865028466 1.69861301764605e-05 0.9999197848691027" />
        <limit lower="-1.570796" upper="0.0" effort="1000000" velocity="1000000" />
    </joint>
    <joint name="motor_upper_leg_below_a-v1_Rigid-75" type="fixed">
        <origin xyz="0.03459583860688417 -0.0003098853626108422 0.00043820898423484243" rpy="9.65767439436126e-11 -1.7276031814969161e-13 -7.625088341983723e-09" />
        <parent link="motor_upper_leg_below_a-v1" />
        <child link="battery_bracket_upper_a" />
    </joint>
    <joint name="motor_upper_leg_below_a-v1_Revolute-79" type="revolute">
        <origin xyz="0.017298284960068334 0.0038449374519823466 0.0030192686955481654" rpy="9.657674738595449e-11 -1.7280017401447522e-13 -7.625088612600583e-09" />
        <parent link="motor_upper_leg_below_a-v1" />
        <child link="outer_ball_bearing2-v1" />
        <axis xyz="0.012665426731662205 -1.7011198854498416e-05 -0.9999197902663612" />
        <limit lower="-0.785398" upper="0.785398" effort="1000000" velocity="1000000" />
    </joint>
    <joint name="outer_ball_bearing2-v1_Rigid-80" type="fixed">
        <origin xyz="-0.01082550333392124 -0.0021975645001456813 0.003663222687533585" rpy="0.00031746084587432326 3.9791552601694945e-06 -0.025067323531094907" />
        <parent link="outer_ball_bearing2-v1" />
        <child link="upper_leg_a-v1" />
    </joint>
    <joint name="upper_leg_a-v1_Rigid-81" type="fixed">
        <origin xyz="-0.0007546514425449758 0.06828892506845129 -0.008008349656602439" rpy="-6.059470416749924e-15 2.4957005439438544e-14 4.784107138222637e-13" />
        <parent link="upper_leg_a-v1" />
        <child link="leg_knee_motor-v1" />
    </joint>
    <joint name="leg_knee_motor-v1_Revolute-82" type="revolute">
        <origin xyz="0.010291179794335364 0.04543450891547863 0.011130476748488985" rpy="-3.141592653589793 -1.3014661234562327e-18 -3.469446951953615e-18" />
        <parent link="leg_knee_motor-v1" />
        <child link="Lower_Leg_v2-v1" />
        <axis xyz="-0.012665852865028466 -1.698613017646039e-05 -0.9999197848691028" />
        <limit lower="0.0" upper="1.570796" effort="1000000" velocity="1000000" />
    </joint>
    <joint name="Lower_Leg_v2-v1_Revolute-91" type="revolute">
        <origin xyz="-0.0018703901920376965 -0.11607935265698573 2.5639874673468734e-05" rpy="-0.00031746080034242513 -3.980556913169085e-06 -0.02506731993457346" />
        <parent link="Lower_Leg_v2-v1" />
        <child link="leg_ankle_motor_av1" />
        <axis xyz="-0.012665428134416876 -1.701119885166906e-05 -0.9999197902485933" />
        <limit lower="-0.523599" upper="0.523599" effort="1000000" velocity="1000000" />
    </joint>
    <joint name="leg_ankle_motor_av1_Rigid-100" type="fixed">
        <origin xyz="-0.0147035302151426 -0.012686852946805036 0.011037320127614034" rpy="0.0003174608355128482 -3.977751804137043e-06 0.025067319935806447" />
        <parent link="leg_ankle_motor_av1" />
        <child link="leg_bearing_a-v1" />
    </joint>
    <joint name="leg_ankle_motor_av1_Rigid-101" type="fixed">
        <origin xyz="0.015884732273924024 -0.029308987188928364 0.04065273590339019" rpy="0.0003174608355128482 -3.977751804137043e-06 0.025067319935806447" />
        <parent link="leg_ankle_motor_av1" />
        <child link="down_foot_bearing_a-v1" />
    </joint>
    <joint name="leg_ankle_motor-v1_Rigid-104" type="fixed">
        <origin xyz="0.014706041012047777 0.029610084799868482 0.006066243225915535" rpy="-3.141592653589793 -1.0802041769744641e-16 -3.2959746043559335e-16" />
        <parent link="leg_ankle_motor-v1" />
        <child link="down_foot_bearing-v1" />
    </joint>
    <joint name="down_foot_bearing_a-v1_Rigid-114" type="fixed">
        <origin xyz="0.0062216114847623415 0.008147488650753201 -0.015080143893458723" rpy="1.5457275544345477 -1.5581308005208176 0.001788664985591629" />
        <parent link="down_foot_bearing_a-v1" />
        <child link="ankle_joint_ring1_b" />
    </joint>
    <joint name="ankle_joint_ring1_b_Revolute-115" type="revolute">
        <origin xyz="-9.382676138258716e-09 -0.003799906644559954 -2.7243001687655698e-05" rpy="-3.1415926535897856 1.281457511176191e-14 1.9068829225062433e-18" />
        <parent link="ankle_joint_ring1_b" />
        <child link="biped_ankle_a-v1" />
        <axis xyz="8.375846967722033e-07 -0.9999747140768515 -0.007167518902519215" />
        <limit lower="-0.349066" upper="0.349066" effort="1000000" velocity="1000000" />
    </joint>
    <joint name="biped_ankle_a-v1_Rigid-117" type="fixed">
        <origin xyz="8.11847487014461e-10 0.00499986367841533 3.582748752286147e-05" rpy="1.4467593789646567e-15 1.3719501066895151e-14 -3.340486185734147e-20" />
        <parent link="biped_ankle_a-v1" />
        <child link="anklle_joint_axle-v1" />
    </joint>
    <joint name="down_foot_bearing-v1_Rigid-118" type="fixed">
        <origin xyz="0.00615026899458929 0.008203137323490437 -0.015079250294840599" rpy="1.5457275544345475 -1.5581308005208176 0.0017886649855916451" />
        <parent link="down_foot_bearing-v1" />
        <child link="ankle_joint_ring1_a" />
    </joint>
    <joint name="ankle_joint_ring1_a_Revolute-119" type="revolute">
        <origin xyz="1.368449051852849e-09 -0.003799520437051491 -6.0390765234736854e-05" rpy="-3.1415926535897856 1.2814619157475171e-14 1.724770838846569e-19" />
        <parent link="ankle_joint_ring1_a" />
        <child link="biped_ankle-v1" />
        <axis xyz="6.398674784372572e-07 -0.999873950323163 -0.01589293990249684" />
        <limit lower="-0.349066" upper="0.349066" effort="1000000" velocity="1000000" />
    </joint>
    <joint name="biped_ankle_a-v1_Rigid-120" type="fixed">
        <origin xyz="0.017300781911281548 -0.08934438652148342 0.03936057131472364" rpy="1.4606371667724712e-15 1.3439993746828388e-14 -3.366955965335844e-20" />
        <parent link="biped_ankle_a-v1" />
        <child link="foot_motor_a-v1" />
    </joint>
    <joint name="biped_ankle-v1_Rigid-121" type="fixed">
        <origin xyz="0.017300774210057865 -0.08968446219625156 0.038579401974009546" rpy="1.4571677198205184e-15 1.3440020851882702e-14 1.7014244932378726e-18" />
        <parent link="biped_ankle-v1" />
        <child link="foot_motor-v1" />
    </joint>
    <joint name="biped_ankle-v1_Rigid-122" type="fixed">
        <origin xyz="-8.19933617890456e-09 0.004999374751327146 7.946475335266268e-05" rpy="1.4432899320127039e-15 1.3719524783817676e-14 1.701742130593093e-18" />
        <parent link="biped_ankle-v1" />
        <child link="left_leg_bearing_axle_c-v1" />
    </joint>
</robot>